Workbook

Sheet Resumen
B1: 45809 | C1: Metros
A2: Almacen | B2: =Almacén_MateriaPrima!E150 -> 142797.79
A3: Agujetas / Material activo | B3: =+Agujeta!I168 -> 525808.15
A4: Agujetas / Material inactivo | B4: =Agujeta!I169 -> 223244.92
A5: Caja Individual / Material activo | B5: ='Caja Individual'!E57 -> 135552.4
A6: Caja individual / Material inactivo | B6: ='Caja Individual'!E58 -> 328142.7
A7: Caja Emb | B7: =+Caja_Embarque!J48 -> 73467.378
A8: Etiquetas | B8: =+Tabla3[[#Totals],[Total]] -> 63647.386
A9: Hulera / Material activo | B9: =+Hulera!F55 -> 199063.94
A10: Hulera / Material Inactivo | B10: =Hulera!F56 -> 76760.92
A11: Cargas/hule | B11: =+ROLLOS[[#Totals],[Total]] -> 142656
A12: Suela/inventario/con movimiento | B12: =+Tabla11312[[#Totals],[TOTAL]] -> 18620.65
A13: Suela/inventario/sin movimiento | B13: =+Tabla113[[#Totals],[TOTAL]] -> 664417.85 | D13: Aprox
A14: Tela Virgen / activo | B14: =Inv_TelaVirgenMov!E43 -> 967492.29 | D14: No cuento con precios del Drill
A15: Tela Virgen / inactivo | B15: =+Tabla7[[#Totals],[TOTAL]] -> 3797454.9 | D15: No cuento con precios de algunos materiales
A16: TelaNoAprovechable | B16: =+TelaNoUtilizable!E22 -> 0 | C16: =TelaNoUtilizable!C22 -> 1757 | D16: No cuento con precios de algunos materiales
B18: =SUM(B2:B17) -> 7359127.3 | C18: No incluye IVA

Sheet Inv_TelaVirgenMov
A1: CÓDIGO | B1: DESCRIPCIÓN | C1: METROS | D1: PRECIO X METRO | E1: TOTAL | F1: PRECIO NO INCLUYE IVA
A2: 511 | B2: 511453 AZ25211 | C2: 108 | D2: 67.89 | E2: =Tabla6[[#This Row],[METROS]]*Tabla6[[#This Row],[PRECIO X METRO]] -> 7332.12
A3: 511 | B3: 511473 VE27149 CHIVE | C3: 305 | D3: 67.89 | E3: =Tabla6[[#This Row],[METROS]]*Tabla6[[#This Row],[PRECIO X METRO]] -> 20706.45
A4: 511 | B4: 511426 RO23174 BLOODY RED | C4: 92 | D4: 67.89 | E4: =Tabla6[[#This Row],[METROS]]*Tabla6[[#This Row],[PRECIO X METRO]] -> 6245.88
A5: 511 | B5: 511479 GRIS SMOKED PEARL | C5: 104 | D5: 67.89 | E5: =Tabla6[[#This Row],[METROS]]*Tabla6[[#This Row],[PRECIO X METRO]] -> 7060.56
A6: 511 | B6: LONA BLANCO ESTRELLA 10016 CAUTIFICADO | C6: 512 | D6: 81.78 | E6: =Tabla6[[#This Row],[METROS]]*Tabla6[[#This Row],[PRECIO X METRO]] -> 41871.36
A7: 511 | B7: LONA NEGRA 511 / 79004 CA:42732 | C7: 892 | D7: 86.49 | E7: =Tabla6[[#This Row],[METROS]]*Tabla6[[#This Row],[PRECIO X METRO]] -> 77149.08
A8: 511 | B8: 511314 RO2338 BUGAMBILIA | C8: 195 | D8: 67.89 | E8: =Tabla6[[#This Row],[METROS]]*Tabla6[[#This Row],[PRECIO X METRO]] -> 13238.55
A9: 582 | B9: NUEVA CANASTA NEGRO 79004 C.582270 | C9: 252 | D9: 85.5 | E9: =Tabla6[[#This Row],[METROS]]*Tabla6[[#This Row],[PRECIO X METRO]] -> 21546
A10: 633 | B10: 633582 AZ 25211 BLUE BERRY | C10: 266 | D10: 57.85 | E10: =Tabla6[[#This Row],[METROS]]*Tabla6[[#This Row],[PRECIO X METRO]] -> 15388.1
A11: 633 | B11: 633583 BAL GRAY 28047 | C11: 494 | D11: 57.85 | E11: =Tabla6[[#This Row],[METROS]]*Tabla6[[#This Row],[PRECIO X METRO]] -> 28577.9
A12: 633 | B12: 633589 RO23176 CHILLI PEPPER | C12: 1061 | D12: 57.85 | E12: =Tabla6[[#This Row],[METROS]]*Tabla6[[#This Row],[PRECIO X METRO]] -> 61378.85
A13: 633 | B13: 633598 NGO 79004 | C13: 308 | D13: 57.85 | E13: =Tabla6[[#This Row],[METROS]]*Tabla6[[#This Row],[PRECIO X METRO]] -> 17817.8
... A15: 651 | B15: 651137 AZ25207 BAL NAVY | C15: 570 | D15: 79.05 | E15: =Tabla6[[#This Row],[METROS]]*Tabla6[[#This Row],[PRECIO X METRO]] -> 45058.5
A16: 651 | B16: PLIX TAWNY PORT 651171 RO23182 | C16: =15+1176 -> 1191 | D16: 79.05 | E16: =Tabla6[[#This Row],[METROS]]*Tabla6[[#This Row],[PRECIO X METRO]] -> 94148.55
A17: 651 | B17: 651110 NEGRO 29016 | C17: 3 | D17: 79.05 | E17: =Tabla6[[#This Row],[METROS]]*Tabla6[[#This Row],[PRECIO X METRO]] -> 237.15
A18: 651 | B18: 651111 CHILLI PAPPER 23176 | C18: 717 | D18: 79.05 | E18: =Tabla6[[#This Row],[METROS]]*Tabla6[[#This Row],[PRECIO X METRO]] -> 56678.85
A19: 651 | B19: 651136 GR 28047 BAL GREY | C19: 82 | D19: 79.05 | E19: =Tabla6[[#This Row],[METROS]]*Tabla6[[#This Row],[PRECIO X METRO]] -> 6482.1
A20: 651 | B20: PLIX CHARCOAL GREY 651177 | C20: 225 | D20: 86.49 | E20: =Tabla6[[#This Row],[METROS]]*Tabla6[[#This Row],[PRECIO X METRO]] -> 19460.25
A21: 668 | B21: 6 OZ WILL DOVE | C21: 20 | D21: 80.75 | E21: =Tabla6[[#This Row],[METROS]]*Tabla6[[#This Row],[PRECIO X METRO]] -> 1615
A22: 668 | B22: 668052 GR 28069 GLACIER GRAY | C22: 74 | D22: 80.75 | E22: =Tabla6[[#This Row],[METROS]]*Tabla6[[#This Row],[PRECIO X METRO]] -> 5975.5
A23: 668 | B23: 6OZ BLACK | C23: 30 | D23: 80.75 | E23: =Tabla6[[#This Row],[METROS]]*Tabla6[[#This Row],[PRECIO X METRO]] -> 2422.5
A24: 668 | B24: 6OZ VANS NEGRO | C24: 15 | D24: 80.75 | E24: =Tabla6[[#This Row],[METROS]]*Tabla6[[#This Row],[PRECIO X METRO]] -> 1211.25
A25: 668 | B25: 6OZ BLANCA BLUE WAHS WHITE DC 668021 | C25: 100 | D25: 84.89 | E25: =Tabla6[[#This Row],[METROS]]*Tabla6[[#This Row],[PRECIO X METRO]] -> 8489
A26: 668 | B26: 6OZ NEGRA / BLACK | C26: 75 | D26: 80.75 | E26: =Tabla6[[#This Row],[METROS]]*Tabla6[[#This Row],[PRECIO X METRO]] -> 6056.25
A27: 668 | B27: 6OZ NEGRA DC 668008 29016 BLACK S/A | C27: 822 | D27: 80.75 | E27: =Tabla6[[#This Row],[METROS]]*Tabla6[[#This Row],[PRECIO X METRO]] -> 66376.5
A28: 674 | B28: AWAT | C28: 1525 | D28: 45.38 | E28: =Tabla6[[#This Row],[METROS]]*Tabla6[[#This Row],[PRECIO X METRO]] -> 69204.5
A29: Drill | B29: DRILL CRUDO VANS | C29: 30 | E29: =Tabla6[[#This Row],[METROS]]*Tabla6[[#This Row],[PRECIO X METRO]] -> 0
A30: Látex | B30: LATEX | C30: =(22)*35 -> 770 | D30: 114.73 | E30: =Tabla6[[#This Row],[METROS]]*Tabla6[[#This Row],[PRECIO X METRO]] -> 88342.1
A31: Sarga | B31: ALICANTE | C31: 125 | D31: 26.7241 | E31: =Tabla6[[#This Row],[METROS]]*Tabla6[[#This Row],[PRECIO X METRO]] -> 3340.5125
A32: Sarga | B32: GABARDINA BLANCA C/A | C32: 50 | D32: 57.1 | E32: =Tabla6[[#This Row],[METROS]]*Tabla6[[#This Row],[PRECIO X METRO]] -> 2855
A33: Sarga | B33: GABARDINA NEGRA C/A | C33: 170 | D33: 64.21 | E33: =Tabla6[[#This Row],[METROS]]*Tabla6[[#This Row],[PRECIO X METRO]] -> 10915.7
A34: Sarga | B34: GABARDINA NEGRA S/A | C34: 500 | D34: 61.47 | E34: =Tabla6[[#This Row],[METROS]]*Tabla6[[#This Row],[PRECIO X METRO]] -> 30735
A35: Sarga | B35: GABARDINA CRUDA C/A | C35: 300 | D35: 43.64 | E35: =Tabla6[[#This Row],[METROS]]*Tabla6[[#This Row],[PRECIO X METRO]] -> 13092
A36: Sarga | B36: TOLEDO | C36: 0 | D36: 31.0344 | E36: =Tabla6[[#This Row],[METROS]]*Tabla6[[#This Row],[PRECIO X METRO]] -> 0
A37: Sarga | B37: BARCELONA | C37: 59 | D37: 12.931 | E37: =Tabla6[[#This Row],[METROS]]*Tabla6[[#This Row],[PRECIO X METRO]] -> 762.929
A38: Sarga | B38: SERGE | C38: 300 | D38: 27.756 | E38: =Tabla6[[#This Row],[METROS]]*Tabla6[[#This Row],[PRECIO X METRO]] -> 8326.8
A39: Látex | B39: CRUDA | C39: 0 | D39: 190.2 | E39: =Tabla6[[#This Row],[METROS]]*Tabla6[[#This Row],[PRECIO X METRO]] -> 0
A40: Látex | B40: NEGRA | C40: 475 | D40: 207.58 | E40: =Tabla6[[#This Row],[METROS]]*Tabla6[[#This Row],[PRECIO X METRO]] -> 98600.5
C43: =SUM(C2:C40) -> 12969 | E43: =SUM(E2:E40) -> 967492.29
...

Sheet Inv_TelaVirgen_SinMov
A1: CÓDIGO | B1: DESCRIPCIÓN | C1: METROS FISCAL | D1: METROS REAL | E1: PRECIO X METROS | F1: TOTAL | G1: OBS
A2: 511 | B2: 511 ROSA PALO41 | C2: 41 | E2: 67.89 | F2: =Tabla7[[#This Row],[METROS FISCAL]]*Tabla7[[#This Row],[PRECIO X METROS]] -> 2783.49
A3: 511 | B3: 511463 VI26054 GRAPE WIND | C3: 79 | E3: 67.89 | F3: =Tabla7[[#This Row],[METROS FISCAL]]*Tabla7[[#This Row],[PRECIO X METROS]] -> 5363.31
A4: 511 | B4: 511501 AZ25220 MIDNIGHT | C4: 110 | E4: 67.89 | F4: =Tabla7[[#This Row],[METROS FISCAL]]*Tabla7[[#This Row],[PRECIO X METROS]] -> 7467.9
A5: 511 | B5: 511461 GR28056 PALOMA | C5: 150 | E5: 67.89 | F5: =Tabla7[[#This Row],[METROS FISCAL]]*Tabla7[[#This Row],[PRECIO X METROS]] -> 10183.5
A6: 511 | B6: AZUL TURQUEZA | C6: 68 | E6: 67.89 | F6: =Tabla7[[#This Row],[METROS FISCAL]]*Tabla7[[#This Row],[PRECIO X METROS]] -> 4616.52
A7: 511 | B7: CHARCOAL GRAY 28064 | C7: 319 | E7: 79.271 | F7: =Tabla7[[#This Row],[METROS FISCAL]]*Tabla7[[#This Row],[PRECIO X METROS]] -> 25287.449
A8: 511 | B8: GREY | C8: 25 | E8: 67.89 | F8: =Tabla7[[#This Row],[METROS FISCAL]]*Tabla7[[#This Row],[PRECIO X METROS]] -> 1697.25
A9: 511 | B9: PLUMBAGO | C9: 20 | E9: 67.89 | F9: =Tabla7[[#This Row],[METROS FISCAL]]*Tabla7[[#This Row],[PRECIO X METROS]] -> 1357.8
A10: 511 | B10: VINO | C10: 70 | E10: 67.89 | F10: =Tabla7[[#This Row],[METROS FISCAL]]*Tabla7[[#This Row],[PRECIO X METROS]] -> 4752.3
A11: 582 | B11: NUEVA CANASTA BLANCA | C11: 256 | E11: 78 | F11: =Tabla7[[#This Row],[METROS FISCAL]]*Tabla7[[#This Row],[PRECIO X METROS]] -> 19968
A12: 633 | B12: 633 BUCKTHORN 24134 | C12: 234 | E12: 57.85 | F12: =Tabla7[[#This Row],[METROS FISCAL]]*Tabla7[[#This Row],[PRECIO X METROS]] -> 13536.9
A13: 633 | B13: 633597 VI 26053 ULTRAVIOLET AP/LIG 3% | C13: 143 | E13: 57.85 | F13: =Tabla7[[#This Row],[METROS FISCAL]]*Tabla7[[#This Row],[PRECIO X METROS]] -> 8272.55
... A31: 651 | B31: 651119 CR24118 CORIANDER | C31: 109 | E31: 79.05 | F31: =Tabla7[[#This Row],[METROS FISCAL]]*Tabla7[[#This Row],[PRECIO X METROS]] -> 8616.45
A32: 651 | B32: 651167 CHIVE 27149 | C32: =119+30 -> 149 | E32: 79.05 | F32: =Tabla7[[#This Row],[METROS FISCAL]]*Tabla7[[#This Row],[PRECIO X METROS]] -> 11778.45
A33: 651 | B33: 651178 CAMEO ROSE 22057 | C33: 53 | E33: 79.05 | F33: =Tabla7[[#This Row],[METROS FISCAL]]*Tabla7[[#This Row],[PRECIO X METROS]] -> 4189.65
A34: 651 | B34: 651186 CATHAY SPICE | C34: 116 | E34: 79.05 | F34: =Tabla7[[#This Row],[METROS FISCAL]]*Tabla7[[#This Row],[PRECIO X METROS]] -> 9169.8
A35: 651 | B35: AQUA | C35: 5 | E35: 79.05 | F35: =Tabla7[[#This Row],[METROS FISCAL]]*Tabla7[[#This Row],[PRECIO X METROS]] -> 395.25
A36: 651 | B36: ASH | C36: 15 | E36: 79.05 | F36: =Tabla7[[#This Row],[METROS FISCAL]]*Tabla7[[#This Row],[PRECIO X METROS]] -> 1185.75
A37: 651 | B37: BAL GREY | C37: 106 | E37: 79.05 | F37: =Tabla7[[#This Row],[METROS FISCAL]]*Tabla7[[#This Row],[PRECIO X METROS]] -> 8379.3
A38: 651 | B38: OFF WHITE / CHINA | C38: 1487 | E38: 79.05 | F38: =Tabla7[[#This Row],[METROS FISCAL]]*Tabla7[[#This Row],[PRECIO X METROS]] -> 117547.35
A39: 651 | B39: PLIX AZUL CIELO MUESTRARIO COLOR | C39: 48 | E39: 79.05 | F39: =Tabla7[[#This Row],[METROS FISCAL]]*Tabla7[[#This Row],[PRECIO X METROS]] -> 3794.4
A40: 651 | B40: PLIX BAL NAVY | C40: 30 | E40: 79.05 | F40: =Tabla7[[#This Row],[METROS FISCAL]]*Tabla7[[#This Row],[PRECIO X METROS]] -> 2371.5
A41: 651 | B41: PLIX MOSTAZA SPERRY | C41: 80 | E41: 79.05 | F41: =Tabla7[[#This Row],[METROS FISCAL]]*Tabla7[[#This Row],[PRECIO X METROS]] -> 6324
A42: 651 | B42: PLIX ROSADO FLAMEADO 23103 651174 | C42: 82 | E42: 65.0049 | F42: =Tabla7[[#This Row],[METROS FISCAL]]*Tabla7[[#This Row],[PRECIO X METROS]] -> 5330.4018
A43: 651 | B43: ROJO-10 | C43: 10 | E43: 79.05 | F43: =Tabla7[[#This Row],[METROS FISCAL]]*Tabla7[[#This Row],[PRECIO X METROS]] -> 790.5
A44: 651 | B44: TWILL CHOCOLATE | C44: 1902 | E44: 79.05 | F44: =Tabla7[[#This Row],[METROS FISCAL]]*Tabla7[[#This Row],[PRECIO X METROS]] -> 150353.1
... A89: 1000 | B89: LONA 1000 C/A AZABACHE | C89: 95 | E89: 110.1476 | F89: =Tabla7[[#This Row],[METROS FISCAL]]*Tabla7[[#This Row],[PRECIO X METROS]] -> 10464.022
A90: - | B90: CAMO RED RDBK | C90: 28 | E90: 80.75 | F90: =Tabla7[[#This Row],[METROS FISCAL]]*Tabla7[[#This Row],[PRECIO X METROS]] -> 2261
A91: - | B91: CHAMBRAY AZUL | C91: 449.7248 | F91: =Tabla7[[#This Row],[METROS FISCAL]]*Tabla7[[#This Row],[PRECIO X METROS]] -> 0
A92: - | B92: DIGITAL PRINT GRIDS LMCC | C92: 80 | E92: 80.75 | F92: =Tabla7[[#This Row],[METROS FISCAL]]*Tabla7[[#This Row],[PRECIO X METROS]] -> 6460
A93: - | B93: DIGITAL PRINT GRIDS WBK | C93: 30 | E93: 80.75 | F93: =Tabla7[[#This Row],[METROS FISCAL]]*Tabla7[[#This Row],[PRECIO X METROS]] -> 2422.5
A94: - | B94: LONA AZUL CHINA (ANCHO) | C94: 162 | F94: =Tabla7[[#This Row],[METROS FISCAL]]*Tabla7[[#This Row],[PRECIO X METROS]] -> 0
A95: - | B95: LONA BRAMANTE S/A BLANCO PAM | C95: 1045.5 | E95: 52.5356 | F95: =Tabla7[[#This Row],[METROS FISCAL]]*Tabla7[[#This Row],[PRECIO X METROS]] -> 54925.97
A96: - | B96: LONA VERDE CHINA (ANCHO) | C96: 279 | F96: =Tabla7[[#This Row],[METROS FISCAL]]*Tabla7[[#This Row],[PRECIO X METROS]] -> 0
A97: - | B97: METALLIC ROSE | C97: 163.2416 | F97: =Tabla7[[#This Row],[METROS FISCAL]]*Tabla7[[#This Row],[PRECIO X METROS]] -> 0
A98: - | B98: METALLIC SILVER | C98: 222.452 | F98: =Tabla7[[#This Row],[METROS FISCAL]]*Tabla7[[#This Row],[PRECIO X METROS]] -> 0
A99: - | B99: MEZCLILLA CHINA | C99: 922 | F99: =Tabla7[[#This Row],[METROS FISCAL]]*Tabla7[[#This Row],[PRECIO X METROS]] -> 0
A100: - | B100: POLY CANVAS DIGITAL PRINT GRIDS TQMT | C100: 43.8 | E100: 110.89 | F100: =Tabla7[[#This Row],[METROS FISCAL]]*Tabla7[[#This Row],[PRECIO X METROS]] -> 4856.982
A101: - | B101: RAYAS MARINO APLICACION BASE DN | C101: 84 | E101: 42.83 | F101: =Tabla7[[#This Row],[METROS FISCAL]]*Tabla7[[#This Row],[PRECIO X METROS]] -> 3597.72 | G101: 42402
...

Sheet TelaNoUtilizable
A1: CÓDIGO | B1: DESCRIPCIÓN | C1: METROS | D1: PRECIO X METROS | E1: TOTAL | F1: Obervaciones | G1: Fecha última compra localizada
A2: * | B2: Sintético Grasshopper / Nubuck | C2: =20*50 -> 1000 | E2: =D2*C2 -> 0 | F2: Daño por humedad / Desintegracion
A3: * | B3: Rayas verde / Acopol | C3: 40 | D3: 0 | E3: =D3*C3 -> 0 | F3: Con hongo | G3: 42402
A4: * | B4: Tela AE Gris | C4: 196 | E4: =D4*C4 -> 0 | F4: Mojado / Hongo
A5: * | B5: Tela AE Gris | C5: 118 | E5: =D5*C5 -> 0 | F5: Dañada por animales
A6: * | B6: Tela AE Gris | C6: 100 | E6: =D6*C6 -> 0 | F6: Dañada por animales
A7: * | B7: Tela AE Gris | C7: 50 | E7: =D7*C7 -> 0 | F7: Dañada por animales
A8: * | B8: Tela AE Gris | C8: 20 | E8: =D8*C8 -> 0 | F8: Dañada por animales
A9: * | B9: Sintético Azul Marino | C9: 10 | E9: =D9*C9 -> 0 | F9: Daño por humedad / Desintegracion
A10: * | B10: Sintético Azul Marino | C10: 50 | E10: =D10*C10 -> 0 | F10: Daño por humedad / Desintegracion
A11: * | B11: Sintético Azul Marino | C11: 50 | E11: =D11*C11 -> 0 | F11: Daño por humedad / Desintegracion
A12: * | B12: Sintético Azul Marino | C12: 30 | E12: =D12*C12 -> 0 | F12: Daño por humedad / Desintegracion
A13: * | B13: Twill Navy | C13: 10 | E13: =D13*C13 -> 0 | F13: Con hongo
A14: * | B14: Metallic Rose | C14: 10 | E14: =D14*C14 -> 0 | F14: Con hongo
A15: * | B15: Sintético Negro Pronanya | C15: 40 | E15: =D15*C15 -> 0 | F15: Desprendimiento de acabado
A16: * | B16: Sintético Negro | C16: 10 | E16: =D16*C16 -> 0 | F16: Daño por humedad / Desintegracion
A17: * | B17: Lona Negra | C17: 3 | D17: 0 | E17: =D17*C17 -> 0 | F17: Dañada por animales
A18: * | B18: Plix Off White | C18: 10 | D18: 0 | E18: =D18*C18 -> 0 | F18: Dañada por animales
A19: * | B19: Sintético Blanco | C19: 10 | E19: =D19*C19 -> 0 | F19: Daño por humedad / Desintegracion
C22: =SUM(C2:C21) -> 1757 | E22: =SUM(E2:E21) -> 0

Sheet Hulera
H1: Tipo de cambio | I1: 18.02 | J1: 46010 | K1: Banco de Mx
A2: Materiales | B2: NOMBRE SIMPLE | C2: CANTIDAD | D2: COSTO | E2: Unidad | F2: Importe | G2: OBSERVACIONES | H2: ÚLTIMA COMPRA | I2: PROVEEDOR | J2: Cost/dls o Pesos
A3: ANTIOXIDANTE DANOX 1076 | B3: Antioxidante | C3: 50 | D3: =+IF(Tabla1[[#This Row],[OBSERVACIONES]]="Dólares",Tabla1[[#This Row],[Cost/dls o Pesos]]*$I$1,Tabla1[[#This Row],[Cost/dls o Pesos]]) -> 171.19 | E3: Kg | F3: =+Tabla1[[#This Row],[CANTIDAD]]*Tabla1[[#This Row],[COSTO]] -> 8559.5 | G3: Dólares | H3: 45973 | I3: FATA | J3: 9.5
A4: ANTIOXIDANTE WINGSTAY | B4: Antioxidante | C4: 0 | D4: =+IF(Tabla1[[#This Row],[OBSERVACIONES]]="Dólares",Tabla1[[#This Row],[Cost/dls o Pesos]]*$I$1,Tabla1[[#This Row],[Cost/dls o Pesos]]) -> 10 | E4: Kg | F4: =+Tabla1[[#This Row],[CANTIDAD]]*Tabla1[[#This Row],[COSTO]] -> 0 | J4: 10
A5: CARBONATO DE CALCIO MICRONIZADO 1 | B5: Carbonato de calcio micronizado | C5: 0 | D5: =+IF(Tabla1[[#This Row],[OBSERVACIONES]]="Dólares",Tabla1[[#This Row],[Cost/dls o Pesos]]*$I$1,Tabla1[[#This Row],[Cost/dls o Pesos]]) -> 6 | E5: Kg | F5: =+Tabla1[[#This Row],[CANTIDAD]]*Tabla1[[#This Row],[COSTO]] -> 0 | J5: 6
A6: CARBONATO DE CALCIO PRECIPITAD | B6: Carbonato de calcio precipitado | C6: 400 | D6: =+IF(Tabla1[[#This Row],[OBSERVACIONES]]="Dólares",Tabla1[[#This Row],[Cost/dls o Pesos]]*$I$1,Tabla1[[#This Row],[Cost/dls o Pesos]]) -> 18.5 | E6: Kg | F6: =+Tabla1[[#This Row],[CANTIDAD]]*Tabla1[[#This Row],[COSTO]] -> 7400 | H6: 45973 | I6: FATA | J6: 18.5
A7: MIXLAND S80 GA F500 AZUFRE Bombones | B7: AZUFRE | C7: 50 | D7: =+IF(Tabla1[[#This Row],[OBSERVACIONES]]="Dólares",Tabla1[[#This Row],[Cost/dls o Pesos]]*$I$1,Tabla1[[#This Row],[Cost/dls o Pesos]]) -> 29.0122 | E7: Kg | F7: =+Tabla1[[#This Row],[CANTIDAD]]*Tabla1[[#This Row],[COSTO]] -> 1450.61 | G7: Dólares | H7: 45980 | I7: QUIMIPOL | J7: 1.61
A8: MIXLAND NEW GEN TMTD 80G Bombones | B8: TMT/ Bombones | C8: 80 | D8: =+IF(Tabla1[[#This Row],[OBSERVACIONES]]="Dólares",Tabla1[[#This Row],[Cost/dls o Pesos]]*$I$1,Tabla1[[#This Row],[Cost/dls o Pesos]]) -> 111.0032 | E8: Kg | F8: =+Tabla1[[#This Row],[CANTIDAD]]*Tabla1[[#This Row],[COSTO]] -> 8880.256 | G8: Dólares | H8: 45979 | I8: SUMINISTRO | J8: 6.16
A9: TMTD Polvo | B9: TMT/ Polvo | C9: 0 | D9: =+IF(Tabla1[[#This Row],[OBSERVACIONES]]="Dólares",Tabla1[[#This Row],[Cost/dls o Pesos]]*$I$1,Tabla1[[#This Row],[Cost/dls o Pesos]]) -> 99.11 | E9: Kg | F9: =+Tabla1[[#This Row],[CANTIDAD]]*Tabla1[[#This Row],[COSTO]] -> 0 | G9: Dólares | J9: 5.5
A10: BIOXIDO DE TITANIO R 103 | B10: Bióxido de titanio R-103 | C10: 75 | D10: =+IF(Tabla1[[#This Row],[OBSERVACIONES]]="Dólares",Tabla1[[#This Row],[Cost/dls o Pesos]]*$I$1,Tabla1[[#This Row],[Cost/dls o Pesos]]) -> 68.9 | E10: Kg | F10: =+Tabla1[[#This Row],[CANTIDAD]]*Tabla1[[#This Row],[COSTO]] -> 5167.5 | H10: 45981 | I10: NASEDA | J10: 68.9
A11: AGENTE ANTI UV | B11: ANTI UV | C11: 13 | D11: =+IF(Tabla1[[#This Row],[OBSERVACIONES]]="Dólares",Tabla1[[#This Row],[Cost/dls o Pesos]]*$I$1,Tabla1[[#This Row],[Cost/dls o Pesos]]) -> 390 | E11: Kg | F11: =+Tabla1[[#This Row],[CANTIDAD]]*Tabla1[[#This Row],[COSTO]] -> 5070 | H11: 45791 | I11: CREPÉ | J11: 390
A12: AC EST Q1012 ESCAMAS | B12: Ácido estéarico Q1012 Escamas | C12: 50 | D12: =+IF(Tabla1[[#This Row],[OBSERVACIONES]]="Dólares",Tabla1[[#This Row],[Cost/dls o Pesos]]*$I$1,Tabla1[[#This Row],[Cost/dls o Pesos]]) -> 34.9588 | E12: Kg | F12: =+Tabla1[[#This Row],[CANTIDAD]]*Tabla1[[#This Row],[COSTO]] -> 1747.94 | G12: Dólares | H12: 45980 | I12: QUIMIPOL | J12: 1.94
A13: ACELERANTE M.B.T.S. POLVO (SOVCHEM MBTS POLVO) | B13: MBTS/ Polvo | C13: 0 | D13: =+IF(Tabla1[[#This Row],[OBSERVACIONES]]="Dólares",Tabla1[[#This Row],[Cost/dls o Pesos]]*$I$1,Tabla1[[#This Row],[Cost/dls o Pesos]]) -> 95.506 | E13: Kg | F13: =+Tabla1[[#This Row],[CANTIDAD]]*Tabla1[[#This Row],[COSTO]] -> 0 | G13: Dólares | J13: 5.3
A14: MIXLAND NEW GEN MBTS 75G Bombones | B14: MBTS/ Bombones | C14: 20 | D14: =+IF(Tabla1[[#This Row],[OBSERVACIONES]]="Dólares",Tabla1[[#This Row],[Cost/dls o Pesos]]*$I$1,Tabla1[[#This Row],[Cost/dls o Pesos]]) -> 127.942 | E14: Kg | F14: =+Tabla1[[#This Row],[CANTIDAD]]*Tabla1[[#This Row],[COSTO]] -> 2558.84 | G14: Dólares | H14: 45972 | I14: SUMINISTRO | J14: 7.1
A15: A032 MASTER CREPE NEGRO | C15: 40 | D15: =+IF(Tabla1[[#This Row],[OBSERVACIONES]]="Dólares",Tabla1[[#This Row],[Cost/dls o Pesos]]*$I$1,Tabla1[[#This Row],[Cost/dls o Pesos]]) -> 68.78 | E15: Kg | F15: =+Tabla1[[#This Row],[CANTIDAD]]*Tabla1[[#This Row],[COSTO]] -> 2751.2 | H15: 45947 | I15: VICSOL | J15: 68.78
A16: ACEITE NAFTENICO 100 | B16: ACEITE NAFTENICO 100 | C16: =180*2 -> 360 | D16: =+IF(Tabla1[[#This Row],[OBSERVACIONES]]="Dólares",Tabla1[[#This Row],[Cost/dls o Pesos]]*$I$1,Tabla1[[#This Row],[Cost/dls o Pesos]]) -> 26.5 | E16: Kg | F16: =+Tabla1[[#This Row],[CANTIDAD]]*Tabla1[[#This Row],[COSTO]] -> 9540 | H16: 45980 | I16: CREPÉ | J16: 26.5
A17: AZUFRE EXTRAFINO | B17: Azufre Extrafino | C17: 5 | D17: =+IF(Tabla1[[#This Row],[OBSERVACIONES]]="Dólares",Tabla1[[#This Row],[Cost/dls o Pesos]]*$I$1,Tabla1[[#This Row],[Cost/dls o Pesos]]) -> 24.5 | E17: Kg | F17: =+Tabla1[[#This Row],[CANTIDAD]]*Tabla1[[#This Row],[COSTO]] -> 122.5 | G17: Compra noviembre 2022 | H17: - | I17: - | J17: 24.5
A18: AZUL ULTRA MAR 463 | B18: AZUL ULTRA MAR | C18: 30 | D18: =+IF(Tabla1[[#This Row],[OBSERVACIONES]]="Dólares",Tabla1[[#This Row],[Cost/dls o Pesos]]*$I$1,Tabla1[[#This Row],[Cost/dls o Pesos]]) -> 124.46 | E18: Kg | F18: =+Tabla1[[#This Row],[CANTIDAD]]*Tabla1[[#This Row],[COSTO]] -> 3733.8 | H18: 45771 | I18: NASEDA | J18: 124.46
A19: BAYFERROX CAFE 686 | B19: BAYFERROX CAFE 686 | C19: 7 | D19: =+IF(Tabla1[[#This Row],[OBSERVACIONES]]="Dólares",Tabla1[[#This Row],[Cost/dls o Pesos]]*$I$1,Tabla1[[#This Row],[Cost/dls o Pesos]]) -> 48.86 | E19: Kg | F19: =+Tabla1[[#This Row],[CANTIDAD]]*Tabla1[[#This Row],[COSTO]] -> 342.02 | G19: Última compra localizada 14.06.2021 | H19: - | I19: - | J19: 48.86
A20: BREA CLARA W | B20: Brea Clara | C20: 10 | D20: =+IF(Tabla1[[#This Row],[OBSERVACIONES]]="Dólares",Tabla1[[#This Row],[Cost/dls o Pesos]]*$I$1,Tabla1[[#This Row],[Cost/dls o Pesos]]) -> 48 | E20: Kg | F20: =+Tabla1[[#This Row],[CANTIDAD]]*Tabla1[[#This Row],[COSTO]] -> 480 | H20: 45973 | I20: FATA | J20: 48
A21: CERA *56 | B21: CERA | C21: 25 | D21: =+IF(Tabla1[[#This Row],[OBSERVACIONES]]="Dólares",Tabla1[[#This Row],[Cost/dls o Pesos]]*$I$1,Tabla1[[#This Row],[Cost/dls o Pesos]]) -> 46 | E21: Kg | F21: =+Tabla1[[#This Row],[CANTIDAD]]*Tabla1[[#This Row],[COSTO]] -> 1150 | H21: 45972 | I21: CREPÉ | J21: 46
A22: ESTEARATO DE ZINC T(PROQUIESTAR ZN)(PETRAC ZN) | B22: ESTEREATO DE ZINC | C22: 20 | D22: =+IF(Tabla1[[#This Row],[OBSERVACIONES]]="Dólares",Tabla1[[#This Row],[Cost/dls o Pesos]]*$I$1,Tabla1[[#This Row],[Cost/dls o Pesos]]) -> 75.5038 | E22: Kg | F22: =+Tabla1[[#This Row],[CANTIDAD]]*Tabla1[[#This Row],[COSTO]] -> 1510.076 | G22: Dólares | H22: 45966 | I22: VICSOL | J22: 4.19
A23: HULE EMULPRENE E260 CONCHITAS | B23: HULE EMULPRENE E260 CONCHITAS | C23: 10 | D23: =+IF(Tabla1[[#This Row],[OBSERVACIONES]]="Dólares",Tabla1[[#This Row],[Cost/dls o Pesos]]*$I$1,Tabla1[[#This Row],[Cost/dls o Pesos]]) -> 77.486 | E23: Kg | F23: =+Tabla1[[#This Row],[CANTIDAD]]*Tabla1[[#This Row],[COSTO]] -> 774.86 | G23: Dólares | H23: 45868 | I23: VICSOL | J23: 4.3
A24: IPISA SILANO 69 | B24: IPISA SILANO 69 | C24: 20 | D24: =+IF(Tabla1[[#This Row],[OBSERVACIONES]]="Dólares",Tabla1[[#This Row],[Cost/dls o Pesos]]*$I$1,Tabla1[[#This Row],[Cost/dls o Pesos]]) -> 78.5 | E24: Litros | F24: =+Tabla1[[#This Row],[CANTIDAD]]*Tabla1[[#This Row],[COSTO]] -> 1570 | G24: Última compra localizada 22.06.22 | H24: - | I24: - | J24: 78.5
A25: MICROTARD A | B25: MICROTARD A | C25: 25 | D25: =+IF(Tabla1[[#This Row],[OBSERVACIONES]]="Dólares",Tabla1[[#This Row],[Cost/dls o Pesos]]*$I$1,Tabla1[[#This Row],[Cost/dls o Pesos]]) -> 87.397 | E25: Kg | F25: =+Tabla1[[#This Row],[CANTIDAD]]*Tabla1[[#This Row],[COSTO]] -> 2184.925 | G25: Dólares | H25: 45965 | I25: SUMINISTRO | J25: 4.85
A26: MONO COAT E 304 | B26: MONO COAT E 304 | C26: =14.88*2 -> 29.76 | D26: =+IF(Tabla1[[#This Row],[OBSERVACIONES]]="Dólares",Tabla1[[#This Row],[Cost/dls o Pesos]]*$I$1,Tabla1[[#This Row],[Cost/dls o Pesos]]) -> 522.58 | E26: Kg | F26: =+Tabla1[[#This Row],[CANTIDAD]]*Tabla1[[#This Row],[COSTO]] -> 15551.981 | G26: Dólares | H26: 45959 | I26: FATA | J26: 29
A27: NBR 6850 LG HULE | B27: NBR 6850 LG HULE | C27: 0 | D27: =+IF(Tabla1[[#This Row],[OBSERVACIONES]]="Dólares",Tabla1[[#This Row],[Cost/dls o Pesos]]*$I$1,Tabla1[[#This Row],[Cost/dls o Pesos]]) -> 84.05 | E27: Kg | F27: =+Tabla1[[#This Row],[CANTIDAD]]*Tabla1[[#This Row],[COSTO]] -> 0 | J27: 84.05
A28: OXIDO DE ZINC TRANSPARENTE COREANO | B28: OXIDO DE ZINC TRANSPARENTE COREANO | C28: 100 | D28: =+IF(Tabla1[[#This Row],[OBSERVACIONES]]="Dólares",Tabla1[[#This Row],[Cost/dls o Pesos]]*$I$1,Tabla1[[#This Row],[Cost/dls o Pesos]]) -> 51.357 | E28: Kg | F28: =+Tabla1[[#This Row],[CANTIDAD]]*Tabla1[[#This Row],[COSTO]] -> 5135.7 | G28: Dólares | H28: 45966 | I28: VICSOL | J28: 2.85
A29: PLURACOL E-4000 | B29: PEG-4000 | C29: 100 | D29: =+IF(Tabla1[[#This Row],[OBSERVACIONES]]="Dólares",Tabla1[[#This Row],[Cost/dls o Pesos]]*$I$1,Tabla1[[#This Row],[Cost/dls o Pesos]]) -> 40 | E29: Kg | F29: =+Tabla1[[#This Row],[CANTIDAD]]*Tabla1[[#This Row],[COSTO]] -> 4000 | H29: 45980 | I29: CREPÉ | J29: 40
A30: SILICA HULERA SP-200 GRANULADO | B30: Sílica Granulada | C30: 1900 | D30: =+IF(Tabla1[[#This Row],[OBSERVACIONES]]="Dólares",Tabla1[[#This Row],[Cost/dls o Pesos]]*$I$1,Tabla1[[#This Row],[Cost/dls o Pesos]]) -> 18.02 | E30: Kg | F30: =+Tabla1[[#This Row],[CANTIDAD]]*Tabla1[[#This Row],[COSTO]] -> 34238 | G30: Dólares | H30: 45992 | I30: KAUCHO QUIMICO | J30: 1
A31: STRUKTOL A-60 (PESTIZANTE) | B31: STRUKTOL A-60 (PESTIZANTE) | C31: 20 | D31: =+IF(Tabla1[[#This Row],[OBSERVACIONES]]="Dólares",Tabla1[[#This Row],[Cost/dls o Pesos]]*$I$1,Tabla1[[#This Row],[Cost/dls o Pesos]]) -> 14.58 | E31: Kg | F31: =+Tabla1[[#This Row],[CANTIDAD]]*Tabla1[[#This Row],[COSTO]] -> 291.6 | G31: Última compra localizada 26.11.2020 | H31: - | I31: - | J31: 14.58
A32: RESINA FENÓLICA | B32: RESINA | C32: 25 | D32: =+IF(Tabla1[[#This Row],[OBSERVACIONES]]="Dólares",Tabla1[[#This Row],[Cost/dls o Pesos]]*$I$1,Tabla1[[#This Row],[Cost/dls o Pesos]]) -> 53.159 | E32: Kg | F32: =+Tabla1[[#This Row],[CANTIDAD]]*Tabla1[[#This Row],[COSTO]] -> 1328.975 | G32: Dólares | H32: 45965 | I32: SUMINISTRO | J32: 2.95
A33: SÍLICA MICROPERLA | B33: SÍLICA MICROPERLA | C33: 40 | D33: =+IF(Tabla1[[#This Row],[OBSERVACIONES]]="Dólares",Tabla1[[#This Row],[Cost/dls o Pesos]]*$I$1,Tabla1[[#This Row],[Cost/dls o Pesos]]) -> 28.832 | E33: Kg | F33: =+Tabla1[[#This Row],[CANTIDAD]]*Tabla1[[#This Row],[COSTO]] -> 1153.28 | G33: Dólares | H33: 45966 | I33: VICSOL | J33: 1.6
A34: PIGMENTO ROJO R2 | B34: PIGMENTO ROJO R2 | C34: 30 | D34: =+IF(Tabla1[[#This Row],[OBSERVACIONES]]="Dólares",Tabla1[[#This Row],[Cost/dls o Pesos]]*$I$1,Tabla1[[#This Row],[Cost/dls o Pesos]]) -> 494 | E34: Kg | F34: =+Tabla1[[#This Row],[CANTIDAD]]*Tabla1[[#This Row],[COSTO]] -> 14820 | G34: No hay compras en sistema de éste material | H34: - | I34: - | J34: 494
A35: PIGMENTO NARANJA H2G2 | B35: PIGMENTO NARANJA H2G2 | C35: 50 | D35: =+IF(Tabla1[[#This Row],[OBSERVACIONES]]="Dólares",Tabla1[[#This Row],[Cost/dls o Pesos]]*$I$1,Tabla1[[#This Row],[Cost/dls o Pesos]]) -> 1055 | E35: Kg | F35: =+Tabla1[[#This Row],[CANTIDAD]]*Tabla1[[#This Row],[COSTO]] -> 52750 | H35: - | I35: - | J35: 1055
A36: PIGMENTO ROJO ÓXIDO | B36: PIGMENTO ROJO ÓXIDO | C36: 20 | D36: =+IF(Tabla1[[#This Row],[OBSERVACIONES]]="Dólares",Tabla1[[#This Row],[Cost/dls o Pesos]]*$I$1,Tabla1[[#This Row],[Cost/dls o Pesos]]) -> 145 | E36: Kg | F36: =+Tabla1[[#This Row],[CANTIDAD]]*Tabla1[[#This Row],[COSTO]] -> 2900 | H36: - | I36: - | J36: 145
A37: PIGMENTO AZUL 7012 | B37: PIGMENTO AZUL 7012 | C37: 4 | D37: =+IF(Tabla1[[#This Row],[OBSERVACIONES]]="Dólares",Tabla1[[#This Row],[Cost/dls o Pesos]]*$I$1,Tabla1[[#This Row],[Cost/dls o Pesos]]) -> 514 | E37: Kg | F37: =+Tabla1[[#This Row],[CANTIDAD]]*Tabla1[[#This Row],[COSTO]] -> 2056 | H37: - | I37: - | J37: 514
A38: PIGMENTO AMARILLO 3GP | B38: AMARILLO 3GP | C38: 10 | D38: =+IF(Tabla1[[#This Row],[OBSERVACIONES]]="Dólares",Tabla1[[#This Row],[Cost/dls o Pesos]]*$I$1,Tabla1[[#This Row],[Cost/dls o Pesos]]) -> 944 | E38: Kg | F38: =+Tabla1[[#This Row],[CANTIDAD]]*Tabla1[[#This Row],[COSTO]] -> 9440 | H38: 45840 | I38: SUMIPLAST | J38: 944
A39: PIGMENTO AMARILLO ÓXIDO | B39: PIGMENTO AMARILLO ÓXIDO | C39: 10 | D39: =+IF(Tabla1[[#This Row],[OBSERVACIONES]]="Dólares",Tabla1[[#This Row],[Cost/dls o Pesos]]*$I$1,Tabla1[[#This Row],[Cost/dls o Pesos]]) -> 944 | E39: Kg | F39: =+Tabla1[[#This Row],[CANTIDAD]]*Tabla1[[#This Row],[COSTO]] -> 9440 | G39: Sin precio, se toma valor de amarillo 3GP | H39: - | I39: - | J39: 944
A40: DIATILENGLICOL | B40: DIETILENGLICOL | C40: 80 | D40: =+IF(Tabla1[[#This Row],[OBSERVACIONES]]="Dólares",Tabla1[[#This Row],[Cost/dls o Pesos]]*$I$1,Tabla1[[#This Row],[Cost/dls o Pesos]]) -> 49.56 | E40: Litros | F40: =+Tabla1[[#This Row],[CANTIDAD]]*Tabla1[[#This Row],[COSTO]] -> 3964.8 | G40: Última compra localizada 21.07.2021 | H40: - | I40: - | J40: 49.56
...

Sheet carga hule
A1: MATERIAL | B1: COLOR | C1: CANTIDAD | D1: Comentarios | E1: PESO X ROLLO (KG) | F1: 19/12/2025 | G1: OBS | H1: Precio | I1: Total
A2: CALZADORES | C2: =ROLLOS[[#This Row],[19/12/2025]]*ROLLOS[[#This Row],[PESO X ROLLO (KG)]] -> 180 | D2: Se realiza en molino | E2: 90 | F2: 2 | H2: 36.1 | I2: =+ROLLOS[[#This Row],[Precio]]*ROLLOS[[#This Row],[CANTIDAD]] -> 6498
A3: PASTA MARCA | C3: =ROLLOS[[#This Row],[19/12/2025]]*ROLLOS[[#This Row],[PESO X ROLLO (KG)]] -> 180 | E3: 90 | F3: 2 | H3: 39.8 | I3: =+ROLLOS[[#This Row],[Precio]]*ROLLOS[[#This Row],[CANTIDAD]] -> 7164
A4: PASTA PARA VIVOS | C4: =ROLLOS[[#This Row],[19/12/2025]]*ROLLOS[[#This Row],[PESO X ROLLO (KG)]] -> 180 | D4: 1 por color (negro, rojo, azul rey y natural) | E4: 60 | F4: 3 | G4: gum, suela calandreada se hace a 60 K, en molino abierto | H4: 39.8 | I4: =+ROLLOS[[#This Row],[Precio]]*ROLLOS[[#This Row],[CANTIDAD]] -> 7164
A5: PASTA SUELA | B5: COLORES | C5: =ROLLOS[[#This Row],[19/12/2025]]*ROLLOS[[#This Row],[PESO X ROLLO (KG)]] -> 630 | D5: Pasta de base | E5: 90 | F5: 7 | H5: 42.9 | I5: =+ROLLOS[[#This Row],[Precio]]*ROLLOS[[#This Row],[CANTIDAD]] -> 27027
A6: PASTA SUELA | B6: BCO LACOSTE | C6: =ROLLOS[[#This Row],[19/12/2025]]*ROLLOS[[#This Row],[PESO X ROLLO (KG)]] -> 360 | D6: Dependiendo el pedido | E6: 90 | F6: 4 | H6: 42.9 | I6: =+ROLLOS[[#This Row],[Precio]]*ROLLOS[[#This Row],[CANTIDAD]] -> 15444
A7: PASTA SUELA | B7: BCO LACOSTE / NUEVO | D7: Dependiendo el pedido | E7: 90 | F7: 0 | I7: =+ROLLOS[[#This Row],[Precio]]*ROLLOS[[#This Row],[CANTIDAD]] -> 0
A8: PASTA SUELA | B8: GUM | D8: Dependiendo el pedido | E8: 90 | F8: 0 | I8: =+ROLLOS[[#This Row],[Precio]]*ROLLOS[[#This Row],[CANTIDAD]] -> 0
A9: PASTA SUELA | B9: NEGRA SKECHER | D9: Revisar para usar en pastas actuales | E9: 90 | F9: 0 | I9: =+ROLLOS[[#This Row],[Precio]]*ROLLOS[[#This Row],[CANTIDAD]] -> 0
A10: PEGAMENTO | B10: BLANCO | D10: Mezclar con pegamento ámbar | F10: 0 | I10: =+ROLLOS[[#This Row],[Precio]]*ROLLOS[[#This Row],[CANTIDAD]] -> 0
A11: PEGAMENTO | B11: Ámbar | C11: =ROLLOS[[#This Row],[19/12/2025]]*ROLLOS[[#This Row],[PESO X ROLLO (KG)]] -> 0 | D11: Revisar inventario | F11: 0.5 | H11: 49.5 | I11: =+ROLLOS[[#This Row],[Precio]]*ROLLOS[[#This Row],[CANTIDAD]] -> 0
A12: RELLENO | B12: AZUL | D12: Inventarios mayores a 1, revisar pedidos | E12: 90 | F12: 0 | I12: =+ROLLOS[[#This Row],[Precio]]*ROLLOS[[#This Row],[CANTIDAD]] -> 0
A13: TIRA | B13: BCO COLLEC | C13: =ROLLOS[[#This Row],[19/12/2025]]*ROLLOS[[#This Row],[PESO X ROLLO (KG)]] -> 810 | E13: 90 | F13: 9 | H13: 39.8 | I13: =+ROLLOS[[#This Row],[Precio]]*ROLLOS[[#This Row],[CANTIDAD]] -> 32238
A14: TIRA | B14: KITS | F14: 0 | I14: =+ROLLOS[[#This Row],[Precio]]*ROLLOS[[#This Row],[CANTIDAD]] -> 0
A15: TIRA | B15: LACOSTE | D15: Dependiendo pedido Se utilizarán 35 rollos | E15: 90 | F15: 0 | I15: =+ROLLOS[[#This Row],[Precio]]*ROLLOS[[#This Row],[CANTIDAD]] -> 0
A16: TIRA | B16: PEYLES | C16: =ROLLOS[[#This Row],[19/12/2025]]*ROLLOS[[#This Row],[PESO X ROLLO (KG)]] -> 90 | D16: DC, POLO, NEXT | E16: 90 | F16: 1 | H16: 39.8 | I16: =+ROLLOS[[#This Row],[Precio]]*ROLLOS[[#This Row],[CANTIDAD]] -> 3582
A17: TIRA | B17: GUM | D17: Sobre pedido DC | E17: 60 | F17: 0 | G17: molino abierto | I17: =+ROLLOS[[#This Row],[Precio]]*ROLLOS[[#This Row],[CANTIDAD]] -> 0
A18: TIRA | B18: PERLA | C18: =ROLLOS[[#This Row],[19/12/2025]]*ROLLOS[[#This Row],[PESO X ROLLO (KG)]] -> 90 | D18: Sobre pedido (Revisar marcas) | E18: 90 | F18: 1 | H18: 39.8 | I18: =+ROLLOS[[#This Row],[Precio]]*ROLLOS[[#This Row],[CANTIDAD]] -> 3582
A19: TIRA | B19: NEGRA | C19: =ROLLOS[[#This Row],[19/12/2025]]*ROLLOS[[#This Row],[PESO X ROLLO (KG)]] -> 990 | E19: 90 | F19: 11 | H19: 38.8 | I19: =+ROLLOS[[#This Row],[Precio]]*ROLLOS[[#This Row],[CANTIDAD]] -> 38412
A20: TIRA | B20: SUPERGA | D20: Sobre pedido | E20: 90 | F20: 0 | I20: =+ROLLOS[[#This Row],[Precio]]*ROLLOS[[#This Row],[CANTIDAD]] -> 0
A21: TIRA | B21: NARANJA | D21: Sobre pedido | E21: 90 | F21: 0 | I21: =+ROLLOS[[#This Row],[Precio]]*ROLLOS[[#This Row],[CANTIDAD]] -> 0
A22: TIRA | B22: ROJA | D22: Sobre pedido | E22: 90 | F22: 0 | I22: =+ROLLOS[[#This Row],[Precio]]*ROLLOS[[#This Row],[CANTIDAD]] -> 0
A23: TIRA | B23: VINO | D23: Sobre pedido | E23: 90 | F23: 0 | I23: =+ROLLOS[[#This Row],[Precio]]*ROLLOS[[#This Row],[CANTIDAD]] -> 0
A24: TIRA | B24: DOVE | D24: Sobre pedido | E24: 90 | F24: 0 | I24: =+ROLLOS[[#This Row],[Precio]]*ROLLOS[[#This Row],[CANTIDAD]] -> 0
A25: TIRA | B25: GRIS RATA | D25: Sobre pedido | E25: 90 | F25: 0 | I25: =+ROLLOS[[#This Row],[Precio]]*ROLLOS[[#This Row],[CANTIDAD]] -> 0
A26: TIRA | B26: GRIS CLARO | D26: Sobre pedido | E26: 90 | F26: 0 | I26: =+ROLLOS[[#This Row],[Precio]]*ROLLOS[[#This Row],[CANTIDAD]] -> 0
A27: TIRA | B27: AMBAR NORMAL | D27: Sobre pedido | E27: 90 | F27: 0 | I27: =+ROLLOS[[#This Row],[Precio]]*ROLLOS[[#This Row],[CANTIDAD]] -> 0
A28: TIRA | B28: AMARILLA | D28: Sobre pedido | E28: 90 | F28: 0 | I28: =+ROLLOS[[#This Row],[Precio]]*ROLLOS[[#This Row],[CANTIDAD]] -> 0
A29: TIRA | B29: NATURAL | D29: Básica para muestras | E29: 90 | F29: 0 | I29: =+ROLLOS[[#This Row],[Precio]]*ROLLOS[[#This Row],[CANTIDAD]] -> 0
A30: TIRA | B30: AZUL REY | D30: Sobre pedido | E30: 90 | F30: 0 | I30: =+ROLLOS[[#This Row],[Precio]]*ROLLOS[[#This Row],[CANTIDAD]] -> 0
A31: SUELA | B31: CALANDREADA NAUTICA | C31: =ROLLOS[[#This Row],[19/12/2025]]*ROLLOS[[#This Row],[PESO X ROLLO (KG)]] -> 30 | D31: Náutica | E31: 60 | F31: 0.5 | H31: 51.5 | I31: =+ROLLOS[[#This Row],[Precio]]*ROLLOS[[#This Row],[CANTIDAD]] -> 1545
C32: =SUBTOTAL(109,ROLLOS[CANTIDAD]) -> 3540 | E32: =SUBTOTAL(109,ROLLOS[PESO X ROLLO (KG)]) -> 2340 | I32: =SUBTOTAL(109,ROLLOS[Total]) -> 142656
C34: =SUM(C33:C33) -> 0

Sheet Suela Mov
A1: INVENTARIO DE SUELA
A2: ESTILO | B2: COLOR | C2: TALLA | D2: CANTIDAD | E2: PARES/NONES | F2: PRECIO | G2: TOTAL
A3: Dany | B3: Negro | C3: Varias | D3: =10+10+10+10+35+4+15+10+8+4+5+8 -> 129 | E3: Pares | F3: 12.69 | G3: =+Tabla11312[[#This Row],[PRECIO]]*Tabla11312[[#This Row],[CANTIDAD]] -> 1637.01
A4: Panal | B4: Negro | C4: Varias | D4: =30+40+40+40+40+40+40+40+40+45+40 -> 435 | E4: Pares | F4: 15.11 | G4: =+Tabla11312[[#This Row],[PRECIO]]*Tabla11312[[#This Row],[CANTIDAD]] -> 6572.85
A5: Lacoste | B5: Blanco viejo | C5: Varias | D5: =25+32+45+90 -> 192 | E5: Pares | F5: 15.11 | G5: =+Tabla11312[[#This Row],[PRECIO]]*Tabla11312[[#This Row],[CANTIDAD]] -> 2901.12
A6: Lacoste | B6: Blanco Nuevo | C6: Varias | D6: =35+25+20+20+45+8+10+51 -> 214 | E6: Pares | F6: 15.11 | G6: =+Tabla11312[[#This Row],[PRECIO]]*Tabla11312[[#This Row],[CANTIDAD]] -> 3233.54
A7: Nautica | B7: Marino / Marinero | C7: Varias | D7: =13+12+5+14 -> 44 | E7: Pares | F7: 15.11 | G7: =+Tabla11312[[#This Row],[PRECIO]]*Tabla11312[[#This Row],[CANTIDAD]] -> 664.84
A8: Cons | B8: Café | C8: Varias | D8: =10+13+10+2+3+10+10+14+15+10+10+10+10+10+10+10+10+10+10+10+25+5+12 -> 239 | E8: Pares | F8: 15.11 | G8: =+Tabla11312[[#This Row],[PRECIO]]*Tabla11312[[#This Row],[CANTIDAD]] -> 3611.29
D9: =SUBTOTAL(109,Tabla11312[CANTIDAD]) -> 1253 | G9: =SUBTOTAL(109,Tabla11312[TOTAL]) -> 18620.65

Sheet suela sin  mov
B1: INVENTARIO DE SUELA
B2: ESTILO | C2: COLOR | D2: TALLA | E2: CANTIDAD | F2: PARES/NONES | G2: STATUS | H2: PRECIO | I2: TOTAL | J2: OBS
B3: AMERICAN | C3: BLANCA | D3: DAMA | E3: 1775 | F3: PARES | G3: SIN MOVIMIENTO | H3: 9.68 | I3: =+Tabla113[[#This Row],[CANTIDAD]]*Tabla113[[#This Row],[PRECIO]] -> 17182
B4: ASIA | C4: AMBAR | D4: VARIAS | E4: =895-895 -> 0 | F4: PARES | G4: SIN MOVIMIENTO | H4: 9.68 | I4: =+Tabla113[[#This Row],[CANTIDAD]]*Tabla113[[#This Row],[PRECIO]] -> 0 | J4: Eliminacion de material // 895
B5: CITY | C5: AMBAR | D5: DAMA | E5: =2900-2900 -> 0 | F5: PARES | G5: SIN MOVIMIENTO | H5: 9.68 | I5: =+Tabla113[[#This Row],[CANTIDAD]]*Tabla113[[#This Row],[PRECIO]] -> 0 | J5: Eliminacion de material // 2900
B6: CONS | C6: AMBAR | D6: VARIAS | E6: 1600 | F6: PARES | G6: SIN MOVIMIENTO | H6: 15.11 | I6: =+Tabla113[[#This Row],[CANTIDAD]]*Tabla113[[#This Row],[PRECIO]] -> 24176
B7: DANY | C7: AMBAR | D7: VARIAS | E7: 3155 | F7: PARES | G7: SIN MOVIMIENTO | H7: 12.69 | I7: =+Tabla113[[#This Row],[CANTIDAD]]*Tabla113[[#This Row],[PRECIO]] -> 40036.95
B8: DANY | C8: BLANCA | D8: VARIAS | E8: 1205 | F8: PARES | G8: SIN MOVIMIENTO | H8: 12.69 | I8: =+Tabla113[[#This Row],[CANTIDAD]]*Tabla113[[#This Row],[PRECIO]] -> 15291.45 | J8: Tono anterior
B9: DANY | C9: NEGRA | D9: VARIAS | E9: 3090 | F9: PARES | G9: SIN MOVIMIENTO | H9: 12.69 | I9: =+Tabla113[[#This Row],[CANTIDAD]]*Tabla113[[#This Row],[PRECIO]] -> 39212.1
B10: DC | C10: DC,AZUL MARINO-TRASSE | D10: VARIAS | E10: 296 | F10: PARES | G10: SIN MOVIMIENTO | H10: 14.31 | I10: =+Tabla113[[#This Row],[CANTIDAD]]*Tabla113[[#This Row],[PRECIO]] -> 4235.76
B11: DC | C11: DC,NEGRO-TRASSE | D11: VARIAS | E11: 793 | F11: PARES | G11: SIN MOVIMIENTO | H11: 14.31 | I11: =+Tabla113[[#This Row],[CANTIDAD]]*Tabla113[[#This Row],[PRECIO]] -> 11347.83
B12: DC | C12: DC,BLANCO-TRASSE | D12: VARIAS | E12: 881 | F12: PARES | G12: SIN MOVIMIENTO | H12: 14.31 | I12: =+Tabla113[[#This Row],[CANTIDAD]]*Tabla113[[#This Row],[PRECIO]] -> 12607.11
B13: DC | C13: DC,AMBAR-TRASSE | D13: VARIAS | E13: 459 | F13: PARES | G13: SIN MOVIMIENTO | H13: 14.31 | I13: =+Tabla113[[#This Row],[CANTIDAD]]*Tabla113[[#This Row],[PRECIO]] -> 6568.29
B14: DC | C14: DC,AZUL MARINO-TRASSE | D14: NONES | E14: 20 | F14: PARES | G14: SIN MOVIMIENTO | H14: 14.31 | I14: =+Tabla113[[#This Row],[CANTIDAD]]*Tabla113[[#This Row],[PRECIO]] -> 286.2
B15: DC | C15: DC,NEGRO-TRASSE | D15: NONES | E15: 5 | F15: PARES | G15: SIN MOVIMIENTO | H15: 14.31 | I15: =+Tabla113[[#This Row],[CANTIDAD]]*Tabla113[[#This Row],[PRECIO]] -> 71.55
B16: DC | C16: DC,BLANCO-TRASSE | D16: NONES | E16: 56 | F16: PARES | G16: SIN MOVIMIENTO | H16: 14.31 | I16: =+Tabla113[[#This Row],[CANTIDAD]]*Tabla113[[#This Row],[PRECIO]] -> 801.36
B17: DC | C17: DC,AMBAR-TRASSE | D17: NONES | E17: 10 | F17: PARES | G17: SIN MOVIMIENTO | H17: 14.31 | I17: =+Tabla113[[#This Row],[CANTIDAD]]*Tabla113[[#This Row],[PRECIO]] -> 143.1
B18: HARLEY | C18: AMBAR/INGERTO NEGRO | D18: RETRO | E18: 675 | F18: PARES | G18: SIN MOVIMIENTO | H18: 14.31 | I18: =+Tabla113[[#This Row],[CANTIDAD]]*Tabla113[[#This Row],[PRECIO]] -> 9659.25
B19: HARLEY | C19: AMBAR/INGERTO NEGRO | D19: MINIMAL | E19: 152 | F19: PARES | G19: SIN MOVIMIENTO | H19: 14.31 | I19: =+Tabla113[[#This Row],[CANTIDAD]]*Tabla113[[#This Row],[PRECIO]] -> 2175.12
B20: KAROSSO | C20: AMBAR | D20: VARIAS | E20: 464 | F20: PARES | G20: SIN MOVIMIENTO | H20: 14.31 | I20: =+Tabla113[[#This Row],[CANTIDAD]]*Tabla113[[#This Row],[PRECIO]] -> 6639.84
... B24: PAYLESS | C24: AMBAR | D24: CABALLERO | E24: 3754 | F24: PARES | G24: SIN MOVIMIENTO | H24: 9.68 | I24: =+Tabla113[[#This Row],[CANTIDAD]]*Tabla113[[#This Row],[PRECIO]] -> 36338.72
B25: PAYLESS | C25: AMBAR | D25: NIÑO | E25: =4980-4980 -> 0 | F25: PARES | G25: SIN MOVIMIENTO | H25: 9.68 | I25: =+Tabla113[[#This Row],[CANTIDAD]]*Tabla113[[#This Row],[PRECIO]] -> 0 | J25: Eliminacion de material // 4980
B26: PANAL | C26: MARINO | D26: VARIAS | E26: 1120 | F26: PARES | G26: SIN MOVIMIENTO | H26: 15.11 | I26: =+Tabla113[[#This Row],[CANTIDAD]]*Tabla113[[#This Row],[PRECIO]] -> 16923.2
B27: SKADI | C27: AMBAR | D27: VARIAS | E27: 1422 | F27: PARES | G27: SIN MOVIMIENTO | H27: 15.11 | I27: =+Tabla113[[#This Row],[CANTIDAD]]*Tabla113[[#This Row],[PRECIO]] -> 21486.42
B28: SKECHERS | C28: CAFÉ | D28: NIÑO | E28: 1130 | F28: PARES | G28: SIN MOVIMIENTO | H28: 9.68 | I28: =+Tabla113[[#This Row],[CANTIDAD]]*Tabla113[[#This Row],[PRECIO]] -> 10938.4
B29: SKECHERS | C29: CAFÉ | D29: NIÑA | E29: 1458 | F29: PARES | G29: SIN MOVIMIENTO | H29: 9.68 | I29: =+Tabla113[[#This Row],[CANTIDAD]]*Tabla113[[#This Row],[PRECIO]] -> 14113.44
B30: SKECHERS | C30: NEGRA | D30: H/M | E30: 823 | F30: PARES | G30: SIN MOVIMIENTO | H30: 9.68 | I30: =+Tabla113[[#This Row],[CANTIDAD]]*Tabla113[[#This Row],[PRECIO]] -> 7966.64
B31: SPERRY | C31: AMBAR | D31: VARIAS | E31: 1910 | F31: PARES | G31: SIN MOVIMIENTO | H31: 15.06 | I31: =+Tabla113[[#This Row],[CANTIDAD]]*Tabla113[[#This Row],[PRECIO]] -> 28764.6
B32: VANS | C32: GUM | D32: VARIAS | E32: 5069 | F32: PARES | G32: SIN MOVIMIENTO | H32: =0.98*20 -> 19.6 | I32: =+Tabla113[[#This Row],[CANTIDAD]]*Tabla113[[#This Row],[PRECIO]] -> 99352.4
B33: VANS | C33: BLACK | D33: VARIAS | E33: 4174 | F33: PARES | G33: SIN MOVIMIENTO | H33: =0.98*20 -> 19.6 | I33: =+Tabla113[[#This Row],[CANTIDAD]]*Tabla113[[#This Row],[PRECIO]] -> 81810.4
B34: VANS | C34: PEARL WHITE | D34: VARIAS | E34: 5039 | F34: PARES | G34: SIN MOVIMIENTO | H34: =0.98*20 -> 19.6 | I34: =+Tabla113[[#This Row],[CANTIDAD]]*Tabla113[[#This Row],[PRECIO]] -> 98764.4
E35: =SUBTOTAL(109,Tabla113[CANTIDAD]) -> 46449 | I35: =SUBTOTAL(109,Tabla113[TOTAL]) -> 664417.85

Sheet Almacén_MateriaPrima
B1: Tipo de cambio | C1: 18.02 | D1: 46010 | E1: Banco de Mx | F1: PRECIO NO INCLUYE IVA
A2: INVENTARIO | B2: CANTIDAD | C2: PRECIO | D2: UNIDAD | E2: Importe | F2: OBSERVACIONES
A3: CANDADO 28 mm | B3: =3*2.5 -> 7.5 | C3: 76 | D3: x MILLAR | E3: =Tabla8[[#This Row],[CANTIDAD]]*Tabla8[[#This Row],[PRECIO]] -> 570
A4: CANDADO 31 mm | B4: =5*2.5 -> 12.5 | C4: 76 | D4: x MILLAR | E4: =Tabla8[[#This Row],[CANTIDAD]]*Tabla8[[#This Row],[PRECIO]] -> 950
A5: CANDADO 37 mm | B5: =11*2.5 -> 27.5 | C5: 85 | D5: x MILLAR | E5: =Tabla8[[#This Row],[CANTIDAD]]*Tabla8[[#This Row],[PRECIO]] -> 2337.5
A6: CANDADO 40 mm | B6: =4*2.5 -> 10 | C6: 106.8965 | D6: x MILLAR | E6: =Tabla8[[#This Row],[CANTIDAD]]*Tabla8[[#This Row],[PRECIO]] -> 1068.965
A7: CANDADO 43 mm | B7: =3*2.5 -> 7.5 | C7: 63.44 | D7: x MILLAR | E7: =Tabla8[[#This Row],[CANTIDAD]]*Tabla8[[#This Row],[PRECIO]] -> 475.8
A8: CANDADO 46 mm | B8: =3*2.5 -> 7.5 | C8: 63.44 | D8: x MILLAR | E8: =Tabla8[[#This Row],[CANTIDAD]]*Tabla8[[#This Row],[PRECIO]] -> 475.8
A9: CANDADO 49 mm | B9: =6*2.5 -> 15 | C9: 63.44 | D9: x MILLAR | E9: =Tabla8[[#This Row],[CANTIDAD]]*Tabla8[[#This Row],[PRECIO]] -> 951.6
A10: CANDADO 52 mm | B10: 0 | C10: 199 | D10: x MILLAR | E10: =Tabla8[[#This Row],[CANTIDAD]]*Tabla8[[#This Row],[PRECIO]] -> 0
A11: CANDADO 55 mm | B11: =5*2.5 -> 12.5 | C11: 63.444 | D11: x MILLAR | E11: =Tabla8[[#This Row],[CANTIDAD]]*Tabla8[[#This Row],[PRECIO]] -> 793.05
A12: CANDADO 61 mm | B12: 0 | C12: 63.444 | D12: x MILLAR | E12: =Tabla8[[#This Row],[CANTIDAD]]*Tabla8[[#This Row],[PRECIO]] -> 0
A13: CANDADO 64 mm | B13: =3*2.5 -> 7.5 | C13: 76 | D13: x MILLAR | E13: =Tabla8[[#This Row],[CANTIDAD]]*Tabla8[[#This Row],[PRECIO]] -> 570
A14: CANDADO 67 mm | B14: =2*2.5 -> 5 | C14: 76 | D14: x MILLAR | E14: =Tabla8[[#This Row],[CANTIDAD]]*Tabla8[[#This Row],[PRECIO]] -> 380
A15: CANDADO 70 mm | B15: 0 | C15: 76 | D15: x MILLAR | E15: =Tabla8[[#This Row],[CANTIDAD]]*Tabla8[[#This Row],[PRECIO]] -> 0
A16: PLASTI FLECHA ITEM NR 20PP | B16: 1 | C16: 54.37 | D16: X CAJA (5'000 piezas) | E16: =Tabla8[[#This Row],[CANTIDAD]]*Tabla8[[#This Row],[PRECIO]] -> 54.37
A17: CANDADO LISO 3" | D17: X CAJA (5'000 piezas) | E17: =Tabla8[[#This Row],[CANTIDAD]]*Tabla8[[#This Row],[PRECIO]] -> 0 | F17: Importado
A18: CANDADO LISO 5" | B18: 1 | C18: 189.24 | D18: X CAJA (5'000 piezas) | E18: =Tabla8[[#This Row],[CANTIDAD]]*Tabla8[[#This Row],[PRECIO]] -> 189.24
A19: SILICÓN GRUESO | B19: =2+2 -> 4 | C19: 106.27 | D19: KG | E19: =Tabla8[[#This Row],[CANTIDAD]]*Tabla8[[#This Row],[PRECIO]] -> 425.08
A20: PAPEL COLLEC 30 X 65 | B20: 3 | C20: 505.82 | D20: x MILLAR | E20: =Tabla8[[#This Row],[CANTIDAD]]*Tabla8[[#This Row],[PRECIO]] -> 1517.46 | F20: El precio por millar de este material, con base a una medida 70*90 cm, de la cual se saca cada corte que utilizamos, por ejemplo: En la medida 30*65, son tres cortes del millar de papel de 70*90.
A21: PAPEL COLLEC 36 X 70 | B21: 0 | C21: 505.82 | D21: x MILLAR | E21: =Tabla8[[#This Row],[CANTIDAD]]*Tabla8[[#This Row],[PRECIO]] -> 0
A22: PAPEL COLLEC 40 X 70 | B22: 4 | C22: 505.82 | D22: x MILLAR | E22: =Tabla8[[#This Row],[CANTIDAD]]*Tabla8[[#This Row],[PRECIO]] -> 2023.28 | F22: El precio por millar de este material, con base a una medida 70*90 cm, de la cual se saca cada corte que utilizamos, por ejemplo: En la medida 30*65, son tres cortes del millar de papel de 70*90.
A23: PAPEL DE CHINA BLANCO 15 X 60 | B23: 0 | C23: 0 | D23: x MILLAR | E23: =Tabla8[[#This Row],[CANTIDAD]]*Tabla8[[#This Row],[PRECIO]] -> 0
A24: PAPEL DE CHINA BLANCO 21 X 60 | B24: 0 | C24: 0 | D24: x MILLAR | E24: =Tabla8[[#This Row],[CANTIDAD]]*Tabla8[[#This Row],[PRECIO]] -> 0
A25: PAPEL DE CHINA BLANCO 15 X 70 | B25: 0 | C25: 0 | D25: x MILLAR | E25: =Tabla8[[#This Row],[CANTIDAD]]*Tabla8[[#This Row],[PRECIO]] -> 0
A26: PAPEL DE CHINA BLANCO 25 X 70 | B26: 0 | C26: 0 | D26: x MILLAR | E26: =Tabla8[[#This Row],[CANTIDAD]]*Tabla8[[#This Row],[PRECIO]] -> 0
A27: PAPEL DE CHINA BLANCO 18 X 70 | B27: 0 | C27: 0 | D27: x MILLAR | E27: =Tabla8[[#This Row],[CANTIDAD]]*Tabla8[[#This Row],[PRECIO]] -> 0
A28: PAPEL DE CHINA BLANCO 27 X 70 | B28: 0 | C28: 0 | D28: x MILLAR | E28: =Tabla8[[#This Row],[CANTIDAD]]*Tabla8[[#This Row],[PRECIO]] -> 0
A29: ESTOPA | B29: 0 | C29: 1219 | D29: PACA (50 kg) | E29: =Tabla8[[#This Row],[CANTIDAD]]*Tabla8[[#This Row],[PRECIO]] -> 0
A30: ESCOBAS | B30: 3 | C30: 35 | D30: PZA | E30: =Tabla8[[#This Row],[CANTIDAD]]*Tabla8[[#This Row],[PRECIO]] -> 105
A31: TACHUELAS | B31: 19 | C31: 216.2 | D31: CAJA/1000 | E31: =Tabla8[[#This Row],[CANTIDAD]]*Tabla8[[#This Row],[PRECIO]] -> 4107.8
A32: HOTMELT | B32: 0 | C32: 149 | D32: KG | E32: =Tabla8[[#This Row],[CANTIDAD]]*Tabla8[[#This Row],[PRECIO]] -> 0
A33: PAPEL HIGIENICO(12) | B33: 0 | C33: 0 | D33: CAJA /12 | E33: =Tabla8[[#This Row],[CANTIDAD]]*Tabla8[[#This Row],[PRECIO]] -> 0
A34: GUANTES BLANCO (12) | B34: =4*12 -> 48 | C34: =13.38*0.9 -> 12.042 | D34: PZA | E34: =Tabla8[[#This Row],[CANTIDAD]]*Tabla8[[#This Row],[PRECIO]] -> 578.016
A35: GUANTES GRIS JAPONES(12) | B35: =1*12 -> 12 | C35: =8.28*0.9 -> 7.452 | D35: PZA | E35: =Tabla8[[#This Row],[CANTIDAD]]*Tabla8[[#This Row],[PRECIO]] -> 89.424
A36: FUNDA MOP 60 CM (CHICA) | B36: 2 | C36: 69 | D36: PZA | E36: =Tabla8[[#This Row],[CANTIDAD]]*Tabla8[[#This Row],[PRECIO]] -> 138
A37: FUNDA MOP 90 CM (MEDIANA) | B37: 4 | C37: 92 | D37: PZA | E37: =Tabla8[[#This Row],[CANTIDAD]]*Tabla8[[#This Row],[PRECIO]] -> 368
A38: FUNDA MOP 125 CM (GRANDE) | B38: 2 | C38: 99 | D38: PZA | E38: =Tabla8[[#This Row],[CANTIDAD]]*Tabla8[[#This Row],[PRECIO]] -> 198
A39: RODILLO QUITA PELUSA (80 HOJAS) | B39: 11 | C39: 86.63 | D39: PZA | E39: =Tabla8[[#This Row],[CANTIDAD]]*Tabla8[[#This Row],[PRECIO]] -> 952.93
A40: PEGAMENTO GREEN | B40: 51 | C40: 34.05 | D40: PZA | E40: =Tabla8[[#This Row],[CANTIDAD]]*Tabla8[[#This Row],[PRECIO]] -> 1736.55
...

Sheet Caja Individual
A1: CODIGO | B1: MARCA | C1: MEDIDA | D1: CANTIDAD | E1: Costo Unitario | F1: Importe | G1: OBS
A2: 7047 | B2: AIRWALK | C2: 1 | D2: 255 | E2: 8.66 | F2: =Tabla4[[#This Row],[CANTIDAD]]*Tabla4[[#This Row],[Costo Unitario]] -> 2208.3
A3: 7096 | B3: BLANX | C3: 1 | D3: 450 | E3: 8.7 | F3: =Tabla4[[#This Row],[CANTIDAD]]*Tabla4[[#This Row],[Costo Unitario]] -> 3915
A4: 7022 | B4: COLLEC | C4: 15 / 17½ | D4: 2250 | E4: 3.6 | F4: =Tabla4[[#This Row],[CANTIDAD]]*Tabla4[[#This Row],[Costo Unitario]] -> 8100
A5: 7017 | B5: COLLEC | C5: 18 / 21 | D5: 2750 | E5: 4.1 | F5: =Tabla4[[#This Row],[CANTIDAD]]*Tabla4[[#This Row],[Costo Unitario]] -> 11275
A6: 7036 | B6: COLLEC | C6: 22 / 25 | D6: 10000 | E6: 4.6 | F6: =Tabla4[[#This Row],[CANTIDAD]]*Tabla4[[#This Row],[Costo Unitario]] -> 46000
A7: 7000 | B7: COLLEC | C7: 25 / 28 | D7: 6250 | E7: 4.85 | F7: =Tabla4[[#This Row],[CANTIDAD]]*Tabla4[[#This Row],[Costo Unitario]] -> 30312.5
A8: 7055 | B8: CORE | C8: CHICA | D8: 0 | E8: 9.07 | F8: =Tabla4[[#This Row],[CANTIDAD]]*Tabla4[[#This Row],[Costo Unitario]] -> 0
A9: 7028 | B9: CORE | C9: GRANDE | D9: 400 | E9: 8.65 | F9: =Tabla4[[#This Row],[CANTIDAD]]*Tabla4[[#This Row],[Costo Unitario]] -> 3460
A10: * | B10: CORE | C10: EDICION ESPE. | D10: 361 | E10: 0 | F10: =Tabla4[[#This Row],[CANTIDAD]]*Tabla4[[#This Row],[Costo Unitario]] -> 0 | G10: Sin costo
A11: 16765 | B11: DC | C11: CHICA Diseño 2024 | D11: 350 | E11: 6.35 | F11: =Tabla4[[#This Row],[CANTIDAD]]*Tabla4[[#This Row],[Costo Unitario]] -> 2222.5
A12: 16766 | B12: DC | C12: GRANDE Diseño 2024 | D12: 200 | E12: 7.86 | F12: =Tabla4[[#This Row],[CANTIDAD]]*Tabla4[[#This Row],[Costo Unitario]] -> 1572
A13: 7118 | B13: GOODYEAR | C13: 33X14X12cm | D13: 891 | E13: 10.29 | F13: =Tabla4[[#This Row],[CANTIDAD]]*Tabla4[[#This Row],[Costo Unitario]] -> 9168.39
A14: 7044 | B14: HARLEY DAVIDSON | C14: CHICA | D14: 0 | E14: 4.82 | F14: =Tabla4[[#This Row],[CANTIDAD]]*Tabla4[[#This Row],[Costo Unitario]] -> 0 | G14: Caja desde 2018
A15: 7027 | B15: HARLEY DAVIDSON | C15: MEDIANA | D15: 278 | E15: 8.57 | F15: =Tabla4[[#This Row],[CANTIDAD]]*Tabla4[[#This Row],[Costo Unitario]] -> 2382.46
A16: 7048 | B16: HARLEY DAVIDSON | C16: GRANDE | D16: 809 | E16: 8.86 | F16: =Tabla4[[#This Row],[CANTIDAD]]*Tabla4[[#This Row],[Costo Unitario]] -> 7167.74
A17: 7110 | B17: HARLEY DAVIDSON | C17: XG | D17: 100 | E17: 9.31 | F17: =Tabla4[[#This Row],[CANTIDAD]]*Tabla4[[#This Row],[Costo Unitario]] -> 931
A18: * | B18: HARLEY SIN IMPRESIÓN | C18: GRANDE | D18: 271 | E18: 8.86 | F18: =Tabla4[[#This Row],[CANTIDAD]]*Tabla4[[#This Row],[Costo Unitario]] -> 2401.06 | G18: Blanx - abril 2022
A19: 16787 | B19: KITS | C19: CH 20.3*15*8.5 CM | D19: 533 | E19: 18 | F19: =Tabla4[[#This Row],[CANTIDAD]]*Tabla4[[#This Row],[Costo Unitario]] -> 9594
A20: 16788 | B20: KITS | C20: GDE 26*16*10 CM | D20: 260 | E20: 19.9 | F20: =Tabla4[[#This Row],[CANTIDAD]]*Tabla4[[#This Row],[Costo Unitario]] -> 5174
A21: 7120 | B21: LACOSTE | C21: 280 | D21: 0 | E21: 10.81 | F21: =Tabla4[[#This Row],[CANTIDAD]]*Tabla4[[#This Row],[Costo Unitario]] -> 0
A22: 7121 | B22: LACOSTE | C22: 310 | D22: 266 | E22: 11.85 | F22: =Tabla4[[#This Row],[CANTIDAD]]*Tabla4[[#This Row],[Costo Unitario]] -> 3152.1
A23: 7122 | B23: LACOSTE | C23: 330 | D23: 66 | E23: 12.5 | F23: =Tabla4[[#This Row],[CANTIDAD]]*Tabla4[[#This Row],[Costo Unitario]] -> 825
A24: 7108 | B24: NAUTICA DAMA | C24: 30*18.5*12 | D24: 30 | E24: 11.65 | F24: =Tabla4[[#This Row],[CANTIDAD]]*Tabla4[[#This Row],[Costo Unitario]] -> 349.5
A25: 7109 | B25: NAUTICA CABALLERO | C25: 33*18.5*11 | D25: 320 | E25: 9.11 | F25: =Tabla4[[#This Row],[CANTIDAD]]*Tabla4[[#This Row],[Costo Unitario]] -> 2915.2
A26: 7128 | B26: NAUTICA CABALLERO | C26: 33*22*12 | D26: 10 | E26: 11.94 | F26: =Tabla4[[#This Row],[CANTIDAD]]*Tabla4[[#This Row],[Costo Unitario]] -> 119.4
A27: 7119 | B27: NEXT & CO RONY | C27: 31*21.5*11.5 | D27: 19 | E27: 9.22 | F27: =Tabla4[[#This Row],[CANTIDAD]]*Tabla4[[#This Row],[Costo Unitario]] -> 175.18
A28: 7080 | B28: POLO | C28: 29.5*163.5*10.5*4 | D28: 133 | E28: 7.31 | F28: =Tabla4[[#This Row],[CANTIDAD]]*Tabla4[[#This Row],[Costo Unitario]] -> 972.23
A29: 7082 | B29: SKECHERS | C29: CABALLERO GDE | D29: 116 | E29: 10.56 | F29: =Tabla4[[#This Row],[CANTIDAD]]*Tabla4[[#This Row],[Costo Unitario]] -> 1224.96
A30: 7083 | B30: SKECHERS | C30: CABALLERO CH | D30: 954 | E30: 7.48 | F30: =Tabla4[[#This Row],[CANTIDAD]]*Tabla4[[#This Row],[Costo Unitario]] -> 7135.92
A31: 7081 | B31: SKECHERS | C31: DAMA GDE | D31: 81 | E31: 8.27 | F31: =Tabla4[[#This Row],[CANTIDAD]]*Tabla4[[#This Row],[Costo Unitario]] -> 669.87
A32: 7079 | B32: SKECHERS | C32: DAMA CH | D32: 229 | E32: 7.48 | F32: =Tabla4[[#This Row],[CANTIDAD]]*Tabla4[[#This Row],[Costo Unitario]] -> 1712.92
A33: 7084 | B33: SKECHERS | C33: NIÑA CH | D33: 1100 | E33: 3.4 | F33: =Tabla4[[#This Row],[CANTIDAD]]*Tabla4[[#This Row],[Costo Unitario]] -> 3740 | G33: Caja desde 2021
A34: 7085 | B34: SKECHERS | C34: NIÑA MD | D34: 460 | E34: 4.2 | F34: =Tabla4[[#This Row],[CANTIDAD]]*Tabla4[[#This Row],[Costo Unitario]] -> 1932 | G34: Caja desde 2021
A35: 7074 | B35: SKECHERS | C35: #1 | D35: 1539 | E35: 4.99 | F35: =Tabla4[[#This Row],[CANTIDAD]]*Tabla4[[#This Row],[Costo Unitario]] -> 7679.61
A36: 7076 | B36: SKECHERS | C36: #3 | D36: 3471 | E36: 5.4 | F36: =Tabla4[[#This Row],[CANTIDAD]]*Tabla4[[#This Row],[Costo Unitario]] -> 18743.4
A37: 7078 | B37: SKECHERS | C37: #5 | D37: 4691 | E37: 7.33 | F37: =Tabla4[[#This Row],[CANTIDAD]]*Tabla4[[#This Row],[Costo Unitario]] -> 34385.03
A38: 7105 | B38: SKECHERS (KRAFT) | C38: 225 | D38: 1282 | E38: 4.59 | F38: =Tabla4[[#This Row],[CANTIDAD]]*Tabla4[[#This Row],[Costo Unitario]] -> 5884.38
A39: 7106 | B39: SKECHERS (KRAFT) | C39: 260 | D39: 780 | E39: 4.94 | F39: =Tabla4[[#This Row],[CANTIDAD]]*Tabla4[[#This Row],[Costo Unitario]] -> 3853.2
A40: 7107 | B40: SKECHERS (KRAFT) | C40: 305 | D40: 1050 | E40: 6.7 | F40: =Tabla4[[#This Row],[CANTIDAD]]*Tabla4[[#This Row],[Costo Unitario]] -> 7035
...

Sheet Agujeta
A1: MATERIAL | B1: MARCA | C1: CODIGO | D1: MEDIDA | E1: COLOR | F1: CANTIDAD FISCAL | G1: CANTIDAD | H1: Costo | I1: Importe | J1: OBS
A2: AGUJETA ALG | B2: SUPERGA | C2: 6162 | D2: 95 | E2: AMARILLO | F2: 91 | G2: 91 | H2: 2.62 | I2: =Tabla10[[#This Row],[CANTIDAD]]*Tabla10[[#This Row],[Costo ]] -> 238.42
A3: AGUJETA ALG | B3: SUPERGA | C3: 6154 | D3: 105 | E3: AMARILLO | F3: 44 | G3: 44 | H3: 2.62 | I3: =Tabla10[[#This Row],[CANTIDAD]]*Tabla10[[#This Row],[Costo ]] -> 115.28
A4: AGUJETA ALG | B4: SUPERGA | C4: 6171 | D4: 95 | E4: AZURE LT | F4: =2090-#REF!-#REF! -> #REF! | G4: 2090 | H4: 1.98 | I4: =Tabla10[[#This Row],[CANTIDAD]]*Tabla10[[#This Row],[Costo ]] -> 4138.2 | J4: Factura a Luis
A5: AGUJETA ALG | B5: SUPERGA | C5: 6175 | D5: 105 | E5: AZURE LT | F5: =2090-#REF!-#REF! -> #REF! | G5: 2090 | H5: 1.98 | I5: =Tabla10[[#This Row],[CANTIDAD]]*Tabla10[[#This Row],[Costo ]] -> 4138.2 | J5: Factura a Luis
A6: AGUJETA ALG | B6: SUPERGA | C6: 6180 | D6: 95 | E6: BEIGE ALMOND | F6: 188 | G6: 188 | H6: 1.98 | I6: =Tabla10[[#This Row],[CANTIDAD]]*Tabla10[[#This Row],[Costo ]] -> 372.24
A7: AGUJETA ALG | B7: SUPERGA | C7: 6185 | D7: 105 | E7: BEIGE ALMOND | F7: 42 | G7: 42 | H7: 1.98 | I7: =Tabla10[[#This Row],[CANTIDAD]]*Tabla10[[#This Row],[Costo ]] -> 83.16
A8: AGUJETA ALG | B8: SUPERGA | C8: 6052 | D8: 95 | E8: BLANCA | F8: 3250 | G8: 3250 | H8: 2.62 | I8: =Tabla10[[#This Row],[CANTIDAD]]*Tabla10[[#This Row],[Costo ]] -> 8515
A9: AGUJETA ALG | B9: SUPERGA | C9: 6150 | D9: 105 | E9: BLANCA | F9: =9000-#REF!-#REF! -> #REF! | G9: 6900 | H9: 2.62 | I9: =Tabla10[[#This Row],[CANTIDAD]]*Tabla10[[#This Row],[Costo ]] -> 18078 | J9: Factura a Luis
A10: AGUJETA ALG | B10: SUPERGA | C10: 6181 | D10: 95 | E10: GREY COLOMBA | F10: 114 | G10: 114 | H10: 1.98 | I10: =Tabla10[[#This Row],[CANTIDAD]]*Tabla10[[#This Row],[Costo ]] -> 225.72
A11: AGUJETA ALG | B11: SUPERGA | C11: 6184 | D11: 105 | E11: GREY COLOMBA | F11: 0 | H11: 1.98 | I11: =Tabla10[[#This Row],[CANTIDAD FISCAL]]*Tabla10[[#This Row],[Costo ]] -> 0 | M11: Solo un decimal en cantidad
A12: AGUJETA ALG | B12: SUPERGA | C12: 6159 | D12: 95 | E12: GREY SAG | F12: 438 | G12: 438 | H12: 2.62 | I12: =Tabla10[[#This Row],[CANTIDAD]]*Tabla10[[#This Row],[Costo ]] -> 1147.56
A13: AGUJETA ALG | B13: SUPERGA | C13: 6683 | D13: 105 | E13: GREY SAG | F13: 1560 | G13: 1560 | H13: 2.62 | I13: =Tabla10[[#This Row],[CANTIDAD]]*Tabla10[[#This Row],[Costo ]] -> 4087.2
A14: AGUJETA ALG | B14: SUPERGA | C14: 3232 | D14: 95 | E14: GREY SILVER | F14: 74 | G14: 74 | H14: 2.62 | I14: =Tabla10[[#This Row],[CANTIDAD]]*Tabla10[[#This Row],[Costo ]] -> 193.88
A15: AGUJETA ALG | B15: SUPERGA | C15: 6690 | D15: 105 | E15: GREY SILVER | F15: 51 | G15: 51 | H15: 2.62 | I15: =Tabla10[[#This Row],[CANTIDAD]]*Tabla10[[#This Row],[Costo ]] -> 133.62
A16: AGUJETA ALG | B16: SUPERGA | D16: 95 | E16: GRIS | F16: 50 | G16: 50 | H16: 2.62 | I16: =Tabla10[[#This Row],[CANTIDAD]]*Tabla10[[#This Row],[Costo ]] -> 131
A17: AGUJETA ALG | B17: SUPERGA | D17: 105 | E17: GRIS | F17: 16 | G17: 16 | H17: 2.62 | I17: =Tabla10[[#This Row],[CANTIDAD]]*Tabla10[[#This Row],[Costo ]] -> 41.92
A18: AGUJETA ALG | B18: SUPERGA | C18: 6173 | D18: 95 | E18: LT GREY | F18: 1500 | G18: 1500 | H18: 1.98 | I18: =Tabla10[[#This Row],[CANTIDAD]]*Tabla10[[#This Row],[Costo ]] -> 2970
A19: AGUJETA ALG | B19: SUPERGA | C19: 6177 | D19: 105 | E19: LT GREY | F19: 1496 | G19: 1496 | H19: 1.98 | I19: =Tabla10[[#This Row],[CANTIDAD]]*Tabla10[[#This Row],[Costo ]] -> 2962.08
A20: AGUJETA ALG | B20: SUPERGA | C20: 6092 | D20: 95 | E20: NAVY | F20: 156 | G20: 156 | H20: 2.62 | I20: =Tabla10[[#This Row],[CANTIDAD]]*Tabla10[[#This Row],[Costo ]] -> 408.72
A21: AGUJETA ALG | B21: SUPERGA | C21: 6682 | D21: 105 | E21: NAVY | F21: 960 | G21: 960 | H21: 2.62 | I21: =Tabla10[[#This Row],[CANTIDAD]]*Tabla10[[#This Row],[Costo ]] -> 2515.2
A22: AGUJETA ALG | B22: SUPERGA | C22: 6082 | D22: 95 | E22: NEGRA | F22: 1512 | G22: 1512 | H22: 2.62 | I22: =Tabla10[[#This Row],[CANTIDAD]]*Tabla10[[#This Row],[Costo ]] -> 3961.44
A23: AGUJETA ALG | B23: SUPERGA | C23: 6149 | D23: 105 | E23: NEGRA | F23: 726 | G23: 726 | H23: 2.62 | I23: =Tabla10[[#This Row],[CANTIDAD]]*Tabla10[[#This Row],[Costo ]] -> 1902.12
A24: AGUJETA ALG | B24: SUPERGA | C24: 6172 | D24: 95 | E24: PINK SKIN | F24: 590 | G24: 590 | H24: 1.98 | I24: =Tabla10[[#This Row],[CANTIDAD]]*Tabla10[[#This Row],[Costo ]] -> 1168.2
A25: AGUJETA ALG | B25: SUPERGA | C25: 6176 | D25: 105 | E25: PINK SKIN | F25: 590 | G25: 590 | H25: 1.98 | I25: =Tabla10[[#This Row],[CANTIDAD]]*Tabla10[[#This Row],[Costo ]] -> 1168.2
A26: AGUJETA ALG | B26: SUPERGA | C26: 6160 | D26: 95 | E26: ROJA | F26: 36 | G26: 36 | H26: 2.62 | I26: =Tabla10[[#This Row],[CANTIDAD]]*Tabla10[[#This Row],[Costo ]] -> 94.32
A27: AGUJETA ALG | B27: SUPERGA | C27: 6698 | D27: 105 | E27: ROJA | F27: 43 | G27: 43 | H27: 2.62 | I27: =Tabla10[[#This Row],[CANTIDAD]]*Tabla10[[#This Row],[Costo ]] -> 112.66
A28: AGUJETA ALG | B28: SUPERGA | D28: 95 | E28: ROSA | F28: 25 | G28: 25 | H28: 2.62 | I28: =Tabla10[[#This Row],[CANTIDAD]]*Tabla10[[#This Row],[Costo ]] -> 65.5
A29: AGUJETA ALG | B29: SUPERGA | D29: 95 | E29: VERDE JADE | F29: 33 | G29: 33 | H29: 2.62 | I29: =Tabla10[[#This Row],[CANTIDAD]]*Tabla10[[#This Row],[Costo ]] -> 86.46
A30: AGUJETA ALG | B30: SUPERGA | D30: 105 | E30: VERDE JADE | F30: 56 | G30: 56 | H30: 2.62 | I30: =Tabla10[[#This Row],[CANTIDAD]]*Tabla10[[#This Row],[Costo ]] -> 146.72
A31: AGUJETA ALG | B31: SUPERGA | C31: 6170 | D31: 95 | E31: WHITE AVORIO | F31: 1280 | G31: 1280 | H31: 1.98 | I31: =Tabla10[[#This Row],[CANTIDAD]]*Tabla10[[#This Row],[Costo ]] -> 2534.4
A32: AGUJETA ALG | B32: SUPERGA | C32: 6174 | D32: 105 | E32: WHITE AVORIO | F32: 1280 | G32: 1280 | H32: 1.98 | I32: =Tabla10[[#This Row],[CANTIDAD]]*Tabla10[[#This Row],[Costo ]] -> 2534.4
A33: AGUJETA AME F3 | B33: DC | C33: 6158 | D33: 90 | E33: 18127 GRIS PEWTER | F33: 246 | G33: 246 | H33: 1.98 | I33: =Tabla10[[#This Row],[CANTIDAD]]*Tabla10[[#This Row],[Costo ]] -> 487.08
A34: AGUJETA AME F3 | B34: DC | D34: 90 | E34: AZUL VIEJO | F34: 348 | G34: 348 | H34: 1.98 | I34: =Tabla10[[#This Row],[CANTIDAD]]*Tabla10[[#This Row],[Costo ]] -> 689.04
A35: AGUJETA AME F3 | B35: DC | D35: 90 | E35: BEIGE | F35: 550 | G35: 550 | H35: 1.98 | I35: =Tabla10[[#This Row],[CANTIDAD]]*Tabla10[[#This Row],[Costo ]] -> 1089
A36: AGUJETA AME F3 | B36: DC | C36: 6074 | D36: 90 | E36: BLANCA | F36: 288 | G36: 288 | H36: 1.98 | I36: =Tabla10[[#This Row],[CANTIDAD]]*Tabla10[[#This Row],[Costo ]] -> 570.24
A37: AGUJETA AME F3 | B37: DC | C37: 6120 | D37: 95 | E37: BLANCA | F37: 960 | G37: 960 | H37: 1.98 | I37: =Tabla10[[#This Row],[CANTIDAD]]*Tabla10[[#This Row],[Costo ]] -> 1900.8
